<sdf version='1.4'>
  <model name='at'>
    <link name='at_footprint'>
      <pose>0 0 0 0 -0 0</pose>
      <inertial>
        <pose>0.0102147 -4.41432e-19 1.29665 0 -0 0</pose>
        <mass>503.01</mass>
        <inertia>
          <ixx>528.394</ixx>
          <ixy>-2.26812e-18</ixy>
          <ixz>-0.551345</ixz>
          <iyy>2705.4</iyy>
          <iyz>-1.4343e-19</iyz>
          <izz>3218.76</izz>
        </inertia>
      </inertial>
      <collision name='at_footprint_collision_at_cam'>
        <pose>2.845 0 3.388 0 -0 0</pose>
        <geometry>
          <box>
            <size>0.05 0.05 0.05</size>
          </box>
        </geometry>
        <surface>
          <contact>
            <ode/>
          </contact>
          <friction>
            <ode/>
          </friction>
        </surface>
        <surface>
          <contact>
            <ode/>
          </contact>
          <friction>
            <ode/>
          </friction>
        </surface>
      </collision>
      <collision name='at_footprint_collision_at_chassis'>
        <pose>1.707 0 2.406 0 -0 0</pose>
        <geometry>
          <box>
            <size>2.325 2.495 2.452</size>
          </box>
        </geometry>
        <surface>
          <contact>
            <ode/>
          </contact>
          <friction>
            <ode/>
          </friction>
        </surface>
      </collision>
      <collision name='at_footprint_collision_at_platform'>
        <pose>0 0 1.296 0 -0 0</pose>
        <geometry>
          <box>
            <size>5.69 2.495 0.3</size>
          </box>
        </geometry>
        <surface>
          <contact>
            <ode/>
          </contact>
          <friction>
            <ode/>
          </friction>
        </surface>
      </collision>
      <visual name='at_footprint_visual'>
        <pose>0 0 0 0 -0 0</pose>
        <geometry>
          <box>
            <size>0.01 0.01 0.01</size>
          </box>
        </geometry>
      </visual>
      <visual name='at_footprint_visual_at_cam'>
        <pose>2.845 0 3.388 0 -0 0</pose>
        <geometry>
          <box>
            <size>0.05 0.05 0.05</size>
          </box>
        </geometry>
        <material>
          <script>
            <name>Gazebo/Blue</name>
            <uri>__default__</uri>
          </script>
        </material>
      </visual>
      <visual name='at_footprint_visual_at_chassis'>
        <pose>1.707 0 2.406 0 -0 0</pose>
        <geometry>
          <box>
            <size>2.325 2.495 2.452</size>
          </box>
        </geometry>
        <material>
          <script>
            <name>Gazebo/Orange</name>
            <uri>__default__</uri>
          </script>
        </material>
      </visual>
      <visual name='at_footprint_visual_at_lidar0'>
        <pose>2.845 0 1.4006 0 -0 0</pose>
        <geometry>
          <box>
            <size>0.15 0.15 0.15</size>
          </box>
        </geometry>
        <material>
          <script>
            <name>Gazebo/Blue</name>
            <uri>__default__</uri>
          </script>
        </material>
      </visual>
      <visual name='at_footprint_visual_at_lidar2'>
        <pose>1.138 1.4475 1.4006 0 -0 1.5708</pose>
        <geometry>
          <box>
            <size>0.15 0.15 0.15</size>
          </box>
        </geometry>
        <material>
          <script>
            <name>Gazebo/Blue</name>
            <uri>__default__</uri>
          </script>
        </material>
      </visual>
      <visual name='at_footprint_visual_at_lidar3'>
        <pose>1.138 -1.4475 1.4006 0 0 -1.5708</pose>
        <geometry>
          <box>
            <size>0.15 0.15 0.15</size>
          </box>
        </geometry>
        <material>
          <script>
            <name>Gazebo/Blue</name>
            <uri>__default__</uri>
          </script>
        </material>
      </visual>
      <visual name='at_footprint_visual_at_platform'>
        <pose>0 0 1.296 0 -0 0</pose>
        <geometry>
          <box>
            <size>5.69 2.495 0.3</size>
          </box>
        </geometry>
        <material>
          <script>
            <name>Gazebo/Orange</name>
            <uri>__default__</uri>
          </script>
        </material>
      </visual>
      <velocity_decay>
        <linear>0</linear>
        <angular>0</angular>
      </velocity_decay>
      <velocity_decay>
        <linear>0</linear>
        <angular>0</angular>
      </velocity_decay>
      <velocity_decay>
        <linear>0</linear>
        <angular>0</angular>
      </velocity_decay>
      <velocity_decay>
        <linear>0</linear>
        <angular>0</angular>
      </velocity_decay>
      <sensor name='cam' type='camera'>
        <update_rate>30</update_rate>
        <camera name='head'>
          <horizontal_fov>1.39626</horizontal_fov>
          <image>
            <width>800</width>
            <height>800</height>
            <format>R8G8B8</format>
          </image>
          <clip>
            <near>0.02</near>
            <far>300</far>
          </clip>
          <noise>
            <type>gaussian</type>
            <mean>0</mean>
            <stddev>0.007</stddev>
          </noise>
        </camera>
        <plugin name='camera_controller' filename='libgazebo_ros_camera.so'>
          <alwaysOn>true</alwaysOn>
          <updateRate>0.0</updateRate>
          <cameraName>at/cam</cameraName>
          <imageTopicName>image_raw</imageTopicName>
          <cameraInfoTopicName>camera_info</cameraInfoTopicName>
          <frameName>at/cam</frameName>
          <hackBaseline>0.07</hackBaseline>
          <distortionK1>0.0</distortionK1>
          <distortionK2>0.0</distortionK2>
          <distortionK3>0.0</distortionK3>
          <distortionT1>0.0</distortionT1>
          <distortionT2>0.0</distortionT2>
        </plugin>
        <pose>2.845 0 3.388 0 -0 0</pose>
      </sensor>
      <velocity_decay>
        <linear>0</linear>
        <angular>0</angular>
      </velocity_decay>
      <velocity_decay>
        <linear>0</linear>
        <angular>0</angular>
      </velocity_decay>
      <gravity>1</gravity>
      <self_collide>1</self_collide>
      <gravity>1</gravity>
      <velocity_decay>
        <linear>0</linear>
        <angular>0</angular>
      </velocity_decay>
      <self_collide>0</self_collide>
      <sensor name='lidar0' type='ray'>
        <visualize>1</visualize>
        <update_rate>10</update_rate>
        <ray>
          <scan>
            <horizontal>
              <samples>360</samples>
              <resolution>1</resolution>
              <min_angle>-1.5</min_angle>
              <max_angle>1.5</max_angle>
            </horizontal>
          </scan>
          <range>
            <min>0.1</min>
            <max>50</max>
            <resolution>0.01</resolution>
          </range>
          <noise>
            <type>gaussian</type>
            <mean>0</mean>
            <stddev>0.01</stddev>
          </noise>
        </ray>
        <plugin name='at_lidar0' filename='libgazebo_ros_laser.so'>
          <topicName>at/fl_lidar</topicName>
          <frameName>at_lidar0</frameName>
        </plugin>
        <pose>2.845 0 1.4006 0 -0 0</pose>
      </sensor>
      <gravity>1</gravity>
      <velocity_decay>
        <linear>0</linear>
        <angular>0</angular>
      </velocity_decay>
      <self_collide>0</self_collide>
      <gravity>1</gravity>
      <self_collide>1</self_collide>
      <gravity>1</gravity>
      <velocity_decay>
        <linear>0</linear>
        <angular>0</angular>
      </velocity_decay>
      <self_collide>0</self_collide>
      <sensor name='lidar2' type='ray'>
        <visualize>1</visualize>
        <update_rate>10</update_rate>
        <ray>
          <scan>
            <horizontal>
              <samples>360</samples>
              <resolution>1</resolution>
              <min_angle>-1.5</min_angle>
              <max_angle>1.5</max_angle>
            </horizontal>
          </scan>
          <range>
            <min>0.1</min>
            <max>50</max>
            <resolution>0.01</resolution>
          </range>
          <noise>
            <type>gaussian</type>
            <mean>0</mean>
            <stddev>0.01</stddev>
          </noise>
        </ray>
        <plugin name='at_lidar2' filename='libgazebo_ros_laser.so'>
          <topicName>at/sl_lidar</topicName>
          <frameName>at_lidar2</frameName>
        </plugin>
        <pose>1.138 1.4475 1.4006 0 -0 1.5708</pose>
      </sensor>
      <gravity>1</gravity>
      <velocity_decay>
        <linear>0</linear>
        <angular>0</angular>
      </velocity_decay>
      <self_collide>0</self_collide>
      <gravity>1</gravity>
      <self_collide>1</self_collide>
      <gravity>1</gravity>
      <velocity_decay>
        <linear>0</linear>
        <angular>0</angular>
      </velocity_decay>
      <self_collide>0</self_collide>
      <sensor name='lidar3' type='ray'>
        <visualize>1</visualize>
        <update_rate>10</update_rate>
        <ray>
          <scan>
            <horizontal>
              <samples>360</samples>
              <resolution>1</resolution>
              <min_angle>-1.5</min_angle>
              <max_angle>1.5</max_angle>
            </horizontal>
          </scan>
          <range>
            <min>0.1</min>
            <max>50</max>
            <resolution>0.01</resolution>
          </range>
          <noise>
            <type>gaussian</type>
            <mean>0</mean>
            <stddev>0.01</stddev>
          </noise>
        </ray>
        <plugin name='at_lidar3' filename='libgazebo_ros_laser.so'>
          <topicName>at/sr_lidar</topicName>
          <frameName>at_lidar3</frameName>
        </plugin>
        <pose>1.138 -1.4475 1.4006 0 0 -1.5708</pose>
      </sensor>
    </link>
    <link name='at_bl_hinge'>
      <pose>-1.553 1.1475 0.8345 0 -0 0</pose>
      <inertial>
        <pose>0 0 0 0 -0 0</pose>
        <mass>10</mass>
        <inertia>
          <ixx>0.330447</ixx>
          <ixy>0</ixy>
          <ixz>0</ixz>
          <iyy>0.330447</iyy>
          <iyz>0</iyz>
          <izz>0.0166</izz>
        </inertia>
      </inertial>
      <visual name='at_bl_hinge_visual'>
        <pose>0 0 0 0 -0 0</pose>
        <geometry>
          <box>
            <size>0.1 0.1 0.623</size>
          </box>
        </geometry>
        <material>
          <script>
            <name>Gazebo/Green</name>
            <uri>__default__</uri>
          </script>
        </material>
      </visual>
      <gravity>1</gravity>
      <velocity_decay>
        <linear>0</linear>
        <angular>0</angular>
      </velocity_decay>
      <self_collide>0</self_collide>
      <gravity>1</gravity>
      <self_collide>0</self_collide>
    </link>
    <joint name='at_platform_2_bl_hinge' type='revolute'>
      <child>at_bl_hinge</child>
      <parent>at_footprint</parent>
      <axis>
        <xyz>0 0 1</xyz>
        <limit>
          <lower>-0.942478</lower>
          <upper>0.942478</upper>
          <effort>100000</effort>
          <velocity>1</velocity>
        </limit>
        <dynamics>
          <damping>100</damping>
        </dynamics>
      </axis>
    </joint>
    <link name='at_bl_wheel'>
      <pose>-1.553 1.2225 0.523 -1.5708 0 0</pose>
      <inertial>
        <pose>0 0 0 0 -0 0</pose>
        <mass>100</mass>
        <inertia>
          <ixx>6.83162</ixx>
          <ixy>0</ixy>
          <ixz>0</ixz>
          <iyy>6.83162</iyy>
          <iyz>0</iyz>
          <izz>13.6765</izz>
        </inertia>
      </inertial>
      <collision name='at_bl_wheel_collision'>
        <pose>0 0 0 0 -0 0</pose>
        <geometry>
          <cylinder>
            <length>0.05</length>
            <radius>0.523</radius>
          </cylinder>
        </geometry>
        <surface>
          <contact>
            <ode/>
          </contact>
          <friction>
            <ode>
              <mu>1</mu>
              <mu2>1</mu2>
            </ode>
          </friction>
        </surface>
      </collision>
      <visual name='at_bl_wheel_visual'>
        <pose>0 0 0 0 -0 0</pose>
        <geometry>
          <cylinder>
            <length>0.3</length>
            <radius>0.523</radius>
          </cylinder>
        </geometry>
        <material>
          <script>
            <name>Gazebo/Grey</name>
            <uri>__default__</uri>
          </script>
        </material>
      </visual>
      <gravity>1</gravity>
      <velocity_decay>
        <linear>0</linear>
        <angular>0</angular>
      </velocity_decay>
      <self_collide>0</self_collide>
      <gravity>1</gravity>
      <self_collide>0</self_collide>
    </link>
    <joint name='at_bl_hinge_2_wheel' type='revolute'>
      <child>at_bl_wheel</child>
      <parent>at_bl_hinge</parent>
      <axis>
        <xyz>0 1 3.26795e-07</xyz>
        <limit>
          <lower>-1e+16</lower>
          <upper>1e+16</upper>
        </limit>
        <dynamics>
          <damping>0.2</damping>
        </dynamics>
      </axis>
    </joint>
    <link name='at_br_hinge'>
      <pose>-1.553 -1.1475 0.8345 0 -0 0</pose>
      <inertial>
        <pose>0 0 0 0 -0 0</pose>
        <mass>10</mass>
        <inertia>
          <ixx>0.330447</ixx>
          <ixy>0</ixy>
          <ixz>0</ixz>
          <iyy>0.330447</iyy>
          <iyz>0</iyz>
          <izz>0.0166</izz>
        </inertia>
      </inertial>
      <visual name='at_br_hinge_visual'>
        <pose>0 0 0 0 -0 0</pose>
        <geometry>
          <box>
            <size>0.1 0.1 0.623</size>
          </box>
        </geometry>
        <material>
          <script>
            <name>Gazebo/Green</name>
            <uri>__default__</uri>
          </script>
        </material>
      </visual>
      <gravity>1</gravity>
      <velocity_decay>
        <linear>0</linear>
        <angular>0</angular>
      </velocity_decay>
      <self_collide>0</self_collide>
      <gravity>1</gravity>
      <self_collide>0</self_collide>
    </link>
    <joint name='at_platform_2_br_hinge' type='revolute'>
      <child>at_br_hinge</child>
      <parent>at_footprint</parent>
      <axis>
        <xyz>0 0 1</xyz>
        <limit>
          <lower>-0.942478</lower>
          <upper>0.942478</upper>
          <effort>100000</effort>
          <velocity>1</velocity>
        </limit>
        <dynamics>
          <damping>100</damping>
        </dynamics>
      </axis>
    </joint>
    <link name='at_br_wheel'>
      <pose>-1.553 -1.2225 0.523 -1.5708 0 0</pose>
      <inertial>
        <pose>0 0 0 0 -0 0</pose>
        <mass>100</mass>
        <inertia>
          <ixx>6.83162</ixx>
          <ixy>0</ixy>
          <ixz>0</ixz>
          <iyy>6.83162</iyy>
          <iyz>0</iyz>
          <izz>13.6765</izz>
        </inertia>
      </inertial>
      <collision name='at_br_wheel_collision'>
        <pose>0 0 0 0 -0 0</pose>
        <geometry>
          <cylinder>
            <length>0.05</length>
            <radius>0.523</radius>
          </cylinder>
        </geometry>
        <surface>
          <contact>
            <ode/>
          </contact>
          <friction>
            <ode>
              <mu>1</mu>
              <mu2>1</mu2>
            </ode>
          </friction>
        </surface>
      </collision>
      <visual name='at_br_wheel_visual'>
        <pose>0 0 0 0 -0 0</pose>
        <geometry>
          <cylinder>
            <length>0.3</length>
            <radius>0.523</radius>
          </cylinder>
        </geometry>
        <material>
          <script>
            <name>Gazebo/Grey</name>
            <uri>__default__</uri>
          </script>
        </material>
      </visual>
      <gravity>1</gravity>
      <velocity_decay>
        <linear>0</linear>
        <angular>0</angular>
      </velocity_decay>
      <self_collide>0</self_collide>
      <gravity>1</gravity>
      <self_collide>0</self_collide>
    </link>
    <joint name='at_br_hinge_2_wheel' type='revolute'>
      <child>at_br_wheel</child>
      <parent>at_br_hinge</parent>
      <axis>
        <xyz>0 1 3.26795e-07</xyz>
        <limit>
          <lower>-1e+16</lower>
          <upper>1e+16</upper>
        </limit>
        <dynamics>
          <damping>0.2</damping>
        </dynamics>
      </axis>
    </joint>
    <link name='at_fl_hinge'>
      <pose>1.553 1.1475 0.8345 0 -0 0</pose>
      <inertial>
        <pose>0 0 0 0 -0 0</pose>
        <mass>10</mass>
        <inertia>
          <ixx>0.330447</ixx>
          <ixy>0</ixy>
          <ixz>0</ixz>
          <iyy>0.330447</iyy>
          <iyz>0</iyz>
          <izz>0.0166</izz>
        </inertia>
      </inertial>
      <visual name='at_fl_hinge_visual'>
        <pose>0 0 0 0 -0 0</pose>
        <geometry>
          <box>
            <size>0.1 0.1 0.623</size>
          </box>
        </geometry>
        <material>
          <script>
            <name>Gazebo/Green</name>
            <uri>__default__</uri>
          </script>
        </material>
      </visual>
      <gravity>1</gravity>
      <velocity_decay>
        <linear>0</linear>
        <angular>0</angular>
      </velocity_decay>
      <self_collide>0</self_collide>
      <gravity>1</gravity>
      <self_collide>0</self_collide>
    </link>
    <joint name='at_platform_2_fl_hinge' type='revolute'>
      <child>at_fl_hinge</child>
      <parent>at_footprint</parent>
      <axis>
        <xyz>0 0 1</xyz>
        <limit>
          <lower>-0.942478</lower>
          <upper>0.942478</upper>
          <effort>100000</effort>
          <velocity>1</velocity>
        </limit>
        <dynamics>
          <damping>100</damping>
        </dynamics>
      </axis>
    </joint>
    <link name='at_fl_wheel'>
      <pose>1.553 1.2225 0.523 -1.5708 0 0</pose>
      <inertial>
        <pose>0 0 0 0 -0 0</pose>
        <mass>100</mass>
        <inertia>
          <ixx>6.83162</ixx>
          <ixy>0</ixy>
          <ixz>0</ixz>
          <iyy>6.83162</iyy>
          <iyz>0</iyz>
          <izz>13.6765</izz>
        </inertia>
      </inertial>
      <collision name='at_fl_wheel_collision'>
        <pose>0 0 0 0 -0 0</pose>
        <geometry>
          <cylinder>
            <length>0.05</length>
            <radius>0.523</radius>
          </cylinder>
        </geometry>
        <surface>
          <contact>
            <ode/>
          </contact>
          <friction>
            <ode>
              <mu>1</mu>
              <mu2>1</mu2>
            </ode>
          </friction>
        </surface>
      </collision>
      <visual name='at_fl_wheel_visual'>
        <pose>0 0 0 0 -0 0</pose>
        <geometry>
          <cylinder>
            <length>0.3</length>
            <radius>0.523</radius>
          </cylinder>
        </geometry>
        <material>
          <script>
            <name>Gazebo/Grey</name>
            <uri>__default__</uri>
          </script>
        </material>
      </visual>
      <gravity>1</gravity>
      <velocity_decay>
        <linear>0</linear>
        <angular>0</angular>
      </velocity_decay>
      <self_collide>0</self_collide>
      <gravity>1</gravity>
      <self_collide>0</self_collide>
    </link>
    <joint name='at_fl_hinge_2_wheel' type='revolute'>
      <child>at_fl_wheel</child>
      <parent>at_fl_hinge</parent>
      <axis>
        <xyz>0 1 3.26795e-07</xyz>
        <limit>
          <lower>-1e+16</lower>
          <upper>1e+16</upper>
        </limit>
        <dynamics>
          <damping>0.2</damping>
        </dynamics>
      </axis>
    </joint>
    <link name='at_fr_hinge'>
      <pose>1.553 -1.1475 0.8345 0 -0 0</pose>
      <inertial>
        <pose>0 0 0 0 -0 0</pose>
        <mass>10</mass>
        <inertia>
          <ixx>0.330447</ixx>
          <ixy>0</ixy>
          <ixz>0</ixz>
          <iyy>0.330447</iyy>
          <iyz>0</iyz>
          <izz>0.0166</izz>
        </inertia>
      </inertial>
      <visual name='at_fr_hinge_visual'>
        <pose>0 0 0 0 -0 0</pose>
        <geometry>
          <box>
            <size>0.1 0.1 0.623</size>
          </box>
        </geometry>
        <material>
          <script>
            <name>Gazebo/Green</name>
            <uri>__default__</uri>
          </script>
        </material>
      </visual>
      <gravity>1</gravity>
      <velocity_decay>
        <linear>0</linear>
        <angular>0</angular>
      </velocity_decay>
      <self_collide>0</self_collide>
      <gravity>1</gravity>
      <self_collide>0</self_collide>
    </link>
    <joint name='at_platform_2_fr_hinge' type='revolute'>
      <child>at_fr_hinge</child>
      <parent>at_footprint</parent>
      <axis>
        <xyz>0 0 1</xyz>
        <limit>
          <lower>-0.942478</lower>
          <upper>0.942478</upper>
          <effort>100000</effort>
          <velocity>1</velocity>
        </limit>
        <dynamics>
          <damping>100</damping>
        </dynamics>
      </axis>
    </joint>
    <link name='at_fr_wheel'>
      <pose>1.553 -1.2225 0.523 -1.5708 0 0</pose>
      <inertial>
        <pose>0 0 0 0 -0 0</pose>
        <mass>100</mass>
        <inertia>
          <ixx>6.83162</ixx>
          <ixy>0</ixy>
          <ixz>0</ixz>
          <iyy>6.83162</iyy>
          <iyz>0</iyz>
          <izz>13.6765</izz>
        </inertia>
      </inertial>
      <collision name='at_fr_wheel_collision'>
        <pose>0 0 0 0 -0 0</pose>
        <geometry>
          <cylinder>
            <length>0.05</length>
            <radius>0.523</radius>
          </cylinder>
        </geometry>
        <surface>
          <contact>
            <ode/>
          </contact>
          <friction>
            <ode>
              <mu>1</mu>
              <mu2>1</mu2>
            </ode>
          </friction>
        </surface>
      </collision>
      <visual name='at_fr_wheel_visual'>
        <pose>0 0 0 0 -0 0</pose>
        <geometry>
          <cylinder>
            <length>0.3</length>
            <radius>0.523</radius>
          </cylinder>
        </geometry>
        <material>
          <script>
            <name>Gazebo/Grey</name>
            <uri>__default__</uri>
          </script>
        </material>
      </visual>
      <gravity>1</gravity>
      <velocity_decay>
        <linear>0</linear>
        <angular>0</angular>
      </velocity_decay>
      <self_collide>0</self_collide>
      <gravity>1</gravity>
      <self_collide>0</self_collide>
    </link>
    <joint name='at_fr_hinge_2_wheel' type='revolute'>
      <child>at_fr_wheel</child>
      <parent>at_fr_hinge</parent>
      <axis>
        <xyz>0 1 3.26795e-07</xyz>
        <limit>
          <lower>-1e+16</lower>
          <upper>1e+16</upper>
        </limit>
        <dynamics>
          <damping>0.2</damping>
        </dynamics>
      </axis>
    </joint>
    <plugin name='at_ground_truth' filename='libgazebo_ros_p3d.so'>
      <topicName>at/ground_truth</topicName>
      <frameName>world</frameName>
      <bodyName>at_footprint</bodyName>
      <gaussianNoise>0.0</gaussianNoise>
      <alwaysOn>true</alwaysOn>
      <updateRate>20.0</updateRate>
    </plugin>
    <static>0</static>
    <plugin name='gazebo_ros_control' filename='libgazebo_ros_control.so'>
      <robotNamespace>/at</robotNamespace>
      <controlPeriod>0.001</controlPeriod>
    </plugin>
  </model>
</sdf>

