<?xml version="1.0" ?>
<!-- =================================================================================== -->
<!-- |    This document was autogenerated by xacro from at.xacro                       | -->
<!-- |    EDITING THIS FILE BY HAND IS NOT RECOMMENDED                                 | -->
<!-- =================================================================================== -->
<!-- ~~~~~~~~~~~~~~~~~~~~~~~~~~~~~~~~~~~~~~~~~~~~~~~~~~~~~~~~~~~~~~~~~~~~~~~~~~~~~~~~~~~~~~~~~~~~~~~~~~~~~~~~~~~~~~~~~~~~~~~~
    at MODEL
~~~~~~~~~~~~~~~~~~~~~~~~~~~~~~~~~~~~~~~~~~~~~~~~~~~~~~~~~~~~~~~~~~~~~~~~~~~~~~~~~~~~~~~~~~~~~~~~~~~~~~~~~~~~~~~~~~~~~~~~~~~~~
    Partner: Institut de Robotica i Informatica Industrial (IRI) UPC-CSIC
    authors:  Andreu Corominas-Murtra, acorominas@iri.upc.edu
    Description: This file describes geometry and simulation parameters for the TNO-at, www.cargo-ants.eu
    Units: [m], [rad] (SI)
    Tutorials on urdf gazebo: http://gazebosim.org/tutorials?cat=connect_ros
    Tutorials on urdf description: http://wiki.ros.org/urdf/Tutorials
    Inertia of standard shapes: http://en.wikipedia.org/wiki/List_of_moments_of_inertia 
    Some tips on wheeled robots: http://www.romin.upm.es/wiki/index.php?title=ROS%3ATutorials/Simulate_Your_Robot_in_Gazebo
    More inspirations around ackerman's steering: http://www.rctek.com/technical/handling/ackerman_steering_principle.html
                                                  https://en.wikipedia.org/wiki/Ackermann_steering_geometry
~~~~~~~~~~~~~~~~~~~~~~~~~~~~~~~~~~~~~~~~~~~~~~~~~~~~~~~~~~~~~~~~~~~~~~~~~~~~~~~~~~~~~~~~~~~~~~~~~~~~~~~~~~~~~~~~~~~~~~~~~ -->
<!-- Robot name -->
<robot name="at" xmlns:xacro="http://ros.org/wiki/xacro">
  <!-- Included URDF Files -->
  <gazebo>
    <static>0</static>
  </gazebo>
  <!--     Links -->
  <gazebo reference="at_base_link">
    <gravity>true</gravity>
    <self_collide>true</self_collide>
    <material>Gazebo/Red</material>
  </gazebo>
  <gazebo reference="at_platform">
    <gravity>true</gravity>
    <self_collide>true</self_collide>
    <material>Gazebo/Orange</material>
  </gazebo>
  <gazebo reference="at_chassis">
    <gravity>true</gravity>
    <self_collide>true</self_collide>
    <material>Gazebo/Orange</material>
  </gazebo>
  <gazebo reference="at_fl_hinge">
    <gravity>true</gravity>
    <self_collide>false</self_collide>
    <material>Gazebo/Green</material>
  </gazebo>
  <gazebo reference="at_fr_hinge">
    <gravity>true</gravity>
    <self_collide>false</self_collide>
    <material>Gazebo/Green</material>
  </gazebo>
  <gazebo reference="at_bl_hinge">
    <gravity>true</gravity>
    <self_collide>false</self_collide>
    <material>Gazebo/Green</material>
  </gazebo>
  <gazebo reference="at_br_hinge">
    <gravity>true</gravity>
    <self_collide>false</self_collide>
    <material>Gazebo/Green</material>
  </gazebo>
  <gazebo reference="at_fl_wheel">
    <gravity>true</gravity>
    <self_collide>false</self_collide>
    <mu1>1.</mu1>
    <mu2>1.</mu2>
    <!--        <kp  value="10000000.0" />
        <kd  value="1.0" />
        <fdir1 value="1 0 0"/>        -->
    <material>Gazebo/Grey</material>
  </gazebo>
  <gazebo reference="at_fr_wheel">
    <gravity>true</gravity>
    <self_collide>false</self_collide>
    <mu1>1.</mu1>
    <mu2>1.</mu2>
    <!--        <kp  value="10000000.0" />
        <kd  value="1.0" />
        <fdir1 value="1 0 0"/>        -->
    <material>Gazebo/Grey</material>
  </gazebo>
  <gazebo reference="at_bl_wheel">
    <gravity>true</gravity>
    <self_collide>false</self_collide>
    <mu1>1.</mu1>
    <mu2>1.</mu2>
    <!--        <kp  value="10000000.0" />
        <kd  value="1.0" />
        <fdir1 value="1 0 0"/>        -->
    <material>Gazebo/Grey</material>
  </gazebo>
  <gazebo reference="at_br_wheel">
    <gravity>true</gravity>
    <self_collide>false</self_collide>
    <mu1>1.</mu1>
    <mu2>1.</mu2>
    <!--        <kp  value="10000000.0" />
        <kd  value="1.0" />
        <fdir1 value="1 0 0"/>        -->
    <material>Gazebo/Grey</material>
  </gazebo>
  <gazebo reference="at_lidar0">
    <gravity>true</gravity>
    <self_collide>true</self_collide>
    <material>Gazebo/Blue</material>
  </gazebo>
  <gazebo reference="at_lidar2">
    <gravity>true</gravity>
    <self_collide>true</self_collide>
    <material>Gazebo/Blue</material>
  </gazebo>
  <gazebo reference="at_lidar3">
    <gravity>true</gravity>
    <self_collide>true</self_collide>
    <material>Gazebo/Blue</material>
  </gazebo>
  <gazebo reference="at_cam">
    <gravity>true</gravity>
    <self_collide>true</self_collide>
    <material>Gazebo/Blue</material>
  </gazebo>
  <!--     Lidar plugins -->
  <gazebo reference="at_lidar0">
    <sensor name="lidar0" type="ray">
      <pose>0 0 0 0 0 0</pose>
      <visualize>true</visualize>
      <update_rate>10</update_rate>
      <ray>
        <scan>
          <horizontal>
            <samples>360</samples>
            <resolution>1</resolution>
            <min_angle>-1.5</min_angle>
            <max_angle>1.5</max_angle>
          </horizontal>
        </scan>
        <range>
          <min>0.10</min>
          <max>50.0</max>
          <resolution>0.01</resolution>
        </range>
        <noise>
          <type>gaussian</type>
          <mean>0.0</mean>
          <stddev>0.01</stddev>
        </noise>
      </ray>
      <plugin filename="libgazebo_ros_laser.so" name="at_lidar0">
        <topicName>at/fl_lidar</topicName>
        <frameName>at_lidar0</frameName>
      </plugin>
    </sensor>
  </gazebo>
  <gazebo reference="at_lidar2">
    <sensor name="lidar2" type="ray">
      <pose>0 0 0 0 0 0</pose>
      <visualize>true</visualize>
      <update_rate>10</update_rate>
      <ray>
        <scan>
          <horizontal>
            <samples>360</samples>
            <resolution>1</resolution>
            <min_angle>-1.5</min_angle>
            <max_angle>1.5</max_angle>
          </horizontal>
        </scan>
        <range>
          <min>0.10</min>
          <max>50.0</max>
          <resolution>0.01</resolution>
        </range>
        <noise>
          <type>gaussian</type>
          <mean>0.0</mean>
          <stddev>0.01</stddev>
        </noise>
      </ray>
      <plugin filename="libgazebo_ros_laser.so" name="at_lidar2">
        <topicName>at/sl_lidar</topicName>
        <frameName>at_lidar2</frameName>
      </plugin>
    </sensor>
  </gazebo>
  <gazebo reference="at_lidar3">
    <sensor name="lidar3" type="ray">
      <pose>0 0 0 0 0 0</pose>
      <visualize>true</visualize>
      <update_rate>10</update_rate>
      <ray>
        <scan>
          <horizontal>
            <samples>360</samples>
            <resolution>1</resolution>
            <min_angle>-1.5</min_angle>
            <max_angle>1.5</max_angle>
          </horizontal>
        </scan>
        <range>
          <min>0.10</min>
          <max>50.0</max>
          <resolution>0.01</resolution>
        </range>
        <noise>
          <type>gaussian</type>
          <mean>0.0</mean>
          <stddev>0.01</stddev>
        </noise>
      </ray>
      <plugin filename="libgazebo_ros_laser.so" name="at_lidar3">
        <topicName>at/sr_lidar</topicName>
        <frameName>at_lidar3</frameName>
      </plugin>
    </sensor>
  </gazebo>
  <gazebo reference="at_cam">
    <sensor name="cam" type="camera">
      <update_rate>30.0</update_rate>
      <camera name="head">
        <horizontal_fov>1.3962634</horizontal_fov>
        <image>
          <width>800</width>
          <height>800</height>
          <format>R8G8B8</format>
        </image>
        <clip>
          <near>0.02</near>
          <far>300</far>
        </clip>
        <noise>
          <type>gaussian</type>
          <!-- Noise is sampled independently per pixel on each frame.
               That pixel's noise value is added to each of its color
               channels, which at that point lie in the range [0,1]. -->
          <mean>0.0</mean>
          <stddev>0.007</stddev>
        </noise>
      </camera>
      <plugin filename="libgazebo_ros_camera.so" name="camera_controller">
        <alwaysOn>true</alwaysOn>
        <updateRate>0.0</updateRate>
        <cameraName>at/cam</cameraName>
        <imageTopicName>image_raw</imageTopicName>
        <cameraInfoTopicName>camera_info</cameraInfoTopicName>
        <frameName>at/cam</frameName>
        <hackBaseline>0.07</hackBaseline>
        <distortionK1>0.0</distortionK1>
        <distortionK2>0.0</distortionK2>
        <distortionK3>0.0</distortionK3>
        <distortionT1>0.0</distortionT1>
        <distortionT2>0.0</distortionT2>
      </plugin>
    </sensor>
  </gazebo>
  <!--     Odometry -->
  <!--    <gazebo>
        <plugin name="${robot}_odom" filename="libgazebo_ros_p3d.so">
            <topicName>${robot}/odom</topicName>
            <frameName>world</frameName>
            <bodyName>${robot}_footprint</bodyName>
            <gaussianNoise>0.1</gaussianNoise>
            <alwaysOn>true</alwaysOn>
            <updateRate>20.0</updateRate>
        </plugin>
    </gazebo>        -->
  <!--     Ground Truth -->
  <gazebo>
    <plugin filename="libgazebo_ros_p3d.so" name="at_ground_truth">
      <topicName>at/ground_truth</topicName>
      <frameName>world</frameName>
      <bodyName>at_footprint</bodyName>
      <gaussianNoise>0.0</gaussianNoise>
      <alwaysOn>true</alwaysOn>
      <updateRate>20.0</updateRate>
    </plugin>
  </gazebo>
  <!--     Joint control (steering and driving) -->
  <gazebo>
    <plugin filename="libgazebo_ros_control.so" name="gazebo_ros_control">
      <robotNamespace>/at</robotNamespace>
      <controlPeriod>0.001</controlPeriod>
      <!--100Hz-->
    </plugin>
  </gazebo>
  <!-- user input dimensions  ( DEBUG: all mass values have been divided by 100 )  -->
  <!-- TNO definitions -->
  <!--<xacro:property name="radarbeam_height"   value="0.05" />
<xacro:property name="radarbeam_mountingheight"   value="0.88" />
<xacro:property name="lider_side_mountingheight"   value="0.725" />
<xacro:property name="lider_side_offsetfront"   value="0.65" />
<xacro:property name="arts_mountingheight"	value="2.220" />
<xacro:property name="rtk_mountingheight"	value="1.720" />-->
  <!-- Size of square 'camera' box -->
  <!-- derived dimensions -->
  <!-- ~~~~~~~~~~~~~~~~~~~~~~~~~~~~~~~~~~~~~~~~~~~~~~~~~~~~~~~~~~~~~~~~~~~~~~~~~~~~~~~~~~ -->
  <!-- ~~~~~~~~~~~~~~~~~~~~~~~ BODY AND PLATFORM ~~~~~~~~~~~~~~~~~~~~~~~~~~~~~~~~~~~~~~~~ -->
  <!--
<link name="world">
    <visual>
        <origin xyz="0 0 -0.1" rpy="0 0 0"/>
        <geometry>
            <box size="0.1 0.1 0.2"/>
        </geometry>
        <material name="red">
            <color rgba="1 0. 0. 0.5"/>
        </material>
    </visual>
</link>-->
  <!-- at Footprint Link (at footprint on ground)-->
  <!--<joint name="$world_2_{robot}_footprint" type="floating" >
    <parent link="world"/>
    <child link="${robot}_footprint"/>
    <origin xyz="0 0 0" rpy="0 0 0"/>
</joint>-->
  <link name="at_footprint">
    <visual>
      <origin rpy="0 0 0" xyz="0 0 0"/>
      <geometry>
        <box size="0.01 0.01 0.01"/>
      </geometry>
      <material name="white">
        <color rgba="1 1 1 0.1"/>
      </material>
    </visual>
    <!--  [ WARN] [1434442482.866511790]: The root link at_footprint has an inertia specified in the URDF, but KDL does not support a root link with an inertia.  As a workaround, you can add an extra dummy link to your URDF. -->
    <!--    <inertial> 
      <mass value="0.1" />
      <origin xyz="0 0 0" rpy="0 0 0"/>
      <inertia ixx="0.001" ixy="0.0" ixz="0.0"
               iyy="0.001" iyz="0.0" 
               izz="0.001" />
    </inertial>-->
    <!--    Comment collision below for normal mode: wheels on te ground -->
    <!--    Uncomment collision below for "Podium" mode: Useful to check wheel control without moving at -->
    <!--   <collision>
        <origin xyz="0 0 0" rpy="0 0 0"/>
        <geometry>
            <box size="0.1 0.1 0.1"/>
        </geometry>
    </collision>-->
  </link>
  <!-- at Base Link (at body)-->
  <joint name="at_footprint_2_base" type="fixed">
    <parent link="at_footprint"/>
    <child link="at_base_link"/>
    <origin rpy="0 0 0" xyz="0 0 0.8845"/>
  </joint>
  <link name="at_base_link">
 
</link>
  <!-- at top platform-->
  <joint name="at_base_2_platform" type="fixed">
    <parent link="at_base_link"/>
    <child link="at_platform"/>
    <origin rpy="0 0 0" xyz="0 0 0.4115"/>
  </joint>
  <link name="at_platform">
    <visual>
      <origin rpy="0 0 0" xyz="0 0 0"/>
      <geometry>
        <box size="5.69 2.495 0.3"/>
      </geometry>
      <material name="yellow">
        <color rgba="1.0 0.9 0.0 0.5"/>
      </material>
    </visual>
    <collision>
      <origin rpy="0 0 0" xyz="0 0 0"/>
      <geometry>
        <box size="5.69 2.495 0.3"/>
      </geometry>
    </collision>
    <inertial>
      <mass value="500.0"/>
      <origin rpy="0 0 0" xyz="0 0 0"/>
      <inertia ixx="262.0735375" ixy="0.0" ixz="0.0" iyy="1347.34315" iyz="0.0" izz="1601.9466875"/>
    </inertial>
  </link>
  <!-- at chassis -->
  <joint name="at_platform_2_chassis" type="fixed">
    <parent link="at_platform"/>
    <child link="at_chassis"/>
    <origin rpy="0 0 0" xyz="1.707 0 1.11"/>
  </joint>
  <link name="at_chassis">
    <visual>
      <origin rpy="0 0 0" xyz="0 0 0"/>
      <geometry>
        <box size="2.325 2.495 2.452"/>
      </geometry>
      <material name="purple">
        <color rgba="1.0 0.0 1.0 0.8"/>
      </material>
    </visual>
    <collision>
      <origin rpy="0 0 0" xyz="0 0 0"/>
      <geometry>
        <box size="2.325 2.495 2.452"/>
      </geometry>
    </collision>
    <inertial>
      <mass value="0.01"/>
      <origin rpy="0 0 0" xyz="0 0 0"/>
      <inertia ixx="262.0735375" ixy="0.0" ixz="0.0" iyy="1347.34315" iyz="0.0" izz="1601.9466875"/>
    </inertial>
  </link>
  <!-- ~~~~~~~~~~~~~~~~~~~~~~~~~~~~~~ WHEELS ~~~~~~~~~~~~~~~~~~~~~~~~~~~~~~~~~~~~~~~~~~~~ -->
  <!-- front left hinge-->
  <joint name="at_platform_2_fl_hinge" type="revolute">
    <parent link="at_platform"/>
    <child link="at_fl_hinge"/>
    <axis xyz="0 0 1"/>
    <limit effort="100000." lower="-0.9424776" upper="0.9424776" velocity="1."/>
    <dynamics damping="100."/>
    <origin rpy="0 0 0" xyz="1.553 1.1475 -0.4615"/>
  </joint>
  <!--<joint name="${robot}_platform_2_fl_hinge" type="fixed" >
    <parent link="${robot}_platform"/>
    <child link="${robot}_fl_hinge"/>
    <axis xyz="0 0 1"/>
    <origin xyz="${0.5*platform_length-wheel_radius-0.2} ${0.5*platform_width-0.5*wheel_hinge_width-wheel_width} ${-0.5*platform_height-0.5*wheel_hinge_height}" rpy="0 0 0"/>
</joint>-->
  <link name="at_fl_hinge">
    <visual>
      <origin rpy="0 0 0" xyz="0 0 0"/>
      <geometry>
        <box size="0.1 0.1 0.623"/>
      </geometry>
      <material name="green2">
        <color rgba="0.5 1 0.3 1"/>
      </material>
    </visual>
    <inertial>
      <mass value="10.0"/>
      <origin rpy="0 0 0" xyz="0 0 0"/>
      <inertia ixx="0.33044707" ixy="0.0" ixz="0.0" iyy="0.33044707" iyz="0.0" izz="0.0166"/>
    </inertial>
  </link>
  <!-- front left wheel-->
  <joint name="at_fl_hinge_2_wheel" type="continuous">
    <parent link="at_fl_hinge"/>
    <child link="at_fl_wheel"/>
    <axis xyz="0 0 1"/>
    <limit effort="100000." velocity="3.141592"/>
    <dynamics damping="0.2"/>
    <origin rpy="-1.570796 0 0" xyz="0 0.075 -0.3115"/>
  </joint>
  <link name="at_fl_wheel">
    <visual>
      <origin rpy="0 0 0" xyz="0 0 0"/>
      <geometry>
        <cylinder length="0.3" radius="0.523"/>
      </geometry>
      <material name="grey">
        <color rgba="0.1 0.1 0.1 1"/>
      </material>
    </visual>
    <collision>
      <origin rpy="0 0 0" xyz="0 0 0"/>
      <geometry>
        <cylinder length="0.05" radius="0.523"/>
      </geometry>
    </collision>
    <inertial>
      <mass value="100.0"/>
      <origin rpy="0 0 0" xyz="0 0 0"/>
      <inertia ixx="6.8316221" ixy="0.0" ixz="0.0" iyy="6.8316221" iyz="0.0" izz="13.67645"/>
    </inertial>
  </link>
  <!-- front right hinge-->
  <joint name="at_platform_2_fr_hinge" type="revolute">
    <parent link="at_platform"/>
    <child link="at_fr_hinge"/>
    <axis xyz="0 0 1"/>
    <limit effort="100000." lower="-0.9424776" upper="0.9424776" velocity="1."/>
    <dynamics damping="100."/>
    <origin rpy="0 0 0" xyz="1.553 -1.1475 -0.4615"/>
  </joint>
  <!--<joint name="${robot}_platform_2_fr_hinge" type="fixed" >
    <parent link="${robot}_platform"/>
    <child link="${robot}_fr_hinge"/>
    <axis xyz="0 0 1"/>
    <origin xyz="${0.5*platform_length-wheel_radius-0.2} ${-0.5*platform_width+0.5*wheel_hinge_width+wheel_width} ${-0.5*platform_height-0.5*wheel_hinge_height}" rpy="0 0 0"/>
</joint>-->
  <link name="at_fr_hinge">
    <visual>
      <origin rpy="0 0 0" xyz="0 0 0"/>
      <geometry>
        <box size="0.1 0.1 0.623"/>
      </geometry>
      <material name="green2">
        <color rgba="0.5 1 0.3 1"/>
      </material>
    </visual>
    <inertial>
      <mass value="10.0"/>
      <origin rpy="0 0 0" xyz="0 0 0"/>
      <inertia ixx="0.33044707" ixy="0.0" ixz="0.0" iyy="0.33044707" iyz="0.0" izz="0.0166"/>
    </inertial>
  </link>
  <!-- front right wheel-->
  <joint name="at_fr_hinge_2_wheel" type="continuous">
    <parent link="at_fr_hinge"/>
    <child link="at_fr_wheel"/>
    <axis xyz="0 0 1"/>
    <limit effort="100000." velocity="3.141592"/>
    <dynamics damping="0.2"/>
    <origin rpy="-1.570796 0 0" xyz="0 -0.075 -0.3115"/>
  </joint>
  <link name="at_fr_wheel">
    <visual>
      <origin rpy="0 0 0" xyz="0 0 0"/>
      <geometry>
        <cylinder length="0.3" radius="0.523"/>
      </geometry>
      <material name="grey">
        <color rgba="0.1 0.1 0.1 1"/>
      </material>
    </visual>
    <collision>
      <origin rpy="0 0 0" xyz="0 0 0"/>
      <geometry>
        <cylinder length="0.05" radius="0.523"/>
      </geometry>
    </collision>
    <inertial>
      <mass value="100.0"/>
      <origin rpy="0 0 0" xyz="0 0 0"/>
      <inertia ixx="6.8316221" ixy="0.0" ixz="0.0" iyy="6.8316221" iyz="0.0" izz="13.67645"/>
    </inertial>
  </link>
  <!-- back left hinge-->
  <joint name="at_platform_2_bl_hinge" type="revolute">
    <parent link="at_platform"/>
    <child link="at_bl_hinge"/>
    <axis xyz="0 0 1"/>
    <limit effort="100000." lower="-0.9424776" upper="0.9424776" velocity="1."/>
    <dynamics damping="100."/>
    <origin rpy="0 0 0" xyz="-1.553 1.1475 -0.4615"/>
  </joint>
  <!--<joint name="${robot}_platform_2_bl_hinge" type="fixed" >
    <parent link="${robot}_platform"/>
    <child link="${robot}_bl_hinge"/>
    <axis xyz="0 0 1"/>
    <origin xyz="${-0.5*platform_length+wheel_radius+0.2} ${0.5*platform_width-0.5*wheel_hinge_width-wheel_width} ${-0.5*platform_height-0.5*wheel_hinge_height}" rpy="0 0 0"/>
</joint>-->
  <link name="at_bl_hinge">
    <visual>
      <origin rpy="0 0 0" xyz="0 0 0"/>
      <geometry>
        <box size="0.1 0.1 0.623"/>
      </geometry>
      <material name="green2">
        <color rgba="0.5 1 0.3 1"/>
      </material>
    </visual>
    <inertial>
      <mass value="10.0"/>
      <origin rpy="0 0 0" xyz="0 0 0"/>
      <inertia ixx="0.33044707" ixy="0.0" ixz="0.0" iyy="0.33044707" iyz="0.0" izz="0.0166"/>
    </inertial>
  </link>
  <!-- back left wheel-->
  <joint name="at_bl_hinge_2_wheel" type="continuous">
    <parent link="at_bl_hinge"/>
    <child link="at_bl_wheel"/>
    <axis xyz="0 0 1"/>
    <limit effort="100000." velocity="3.141592"/>
    <dynamics damping="0.2"/>
    <origin rpy="-1.570796 0 0" xyz="0 0.075 -0.3115"/>
  </joint>
  <link name="at_bl_wheel">
    <visual>
      <origin rpy="0 0 0" xyz="0 0 0"/>
      <geometry>
        <cylinder length="0.3" radius="0.523"/>
      </geometry>
      <material name="grey">
        <color rgba="0.1 0.1 0.1 1"/>
      </material>
    </visual>
    <collision>
      <origin rpy="0 0 0" xyz="0 0 0"/>
      <geometry>
        <cylinder length="0.05" radius="0.523"/>
      </geometry>
    </collision>
    <inertial>
      <mass value="100.0"/>
      <origin rpy="0 0 0" xyz="0 0 0"/>
      <inertia ixx="6.8316221" ixy="0.0" ixz="0.0" iyy="6.8316221" iyz="0.0" izz="13.67645"/>
    </inertial>
  </link>
  <!-- back right hinge-->
  <joint name="at_platform_2_br_hinge" type="revolute">
    <parent link="at_platform"/>
    <child link="at_br_hinge"/>
    <axis xyz="0 0 1"/>
    <limit effort="100000." lower="-0.9424776" upper="0.9424776" velocity="1."/>
    <dynamics damping="100."/>
    <origin rpy="0 0 0" xyz="-1.553 -1.1475 -0.4615"/>
  </joint>
  <!--<joint name="${robot}_platform_2_br_hinge" type="fixed" >
    <parent link="${robot}_platform"/>
    <child link="${robot}_br_hinge"/>
    <axis xyz="0 0 1"/>
    <origin xyz="${-0.5*platform_length+wheel_radius+0.2} ${-0.5*platform_width+0.5*wheel_hinge_width+wheel_width} ${-0.5*platform_height-0.5*wheel_hinge_height}" rpy="0 0 0"/>
</joint>-->
  <link name="at_br_hinge">
    <visual>
      <origin rpy="0 0 0" xyz="0 0 0"/>
      <geometry>
        <box size="0.1 0.1 0.623"/>
      </geometry>
      <material name="green2">
        <color rgba="0.5 1 0.3 1"/>
      </material>
    </visual>
    <inertial>
      <mass value="10.0"/>
      <origin rpy="0 0 0" xyz="0 0 0"/>
      <inertia ixx="0.33044707" ixy="0.0" ixz="0.0" iyy="0.33044707" iyz="0.0" izz="0.0166"/>
    </inertial>
  </link>
  <!-- back right wheel-->
  <joint name="at_br_hinge_2_wheel" type="continuous">
    <parent link="at_br_hinge"/>
    <child link="at_br_wheel"/>
    <axis xyz="0 0 1"/>
    <limit effort="100000." velocity="3.141592"/>
    <dynamics damping="0.2"/>
    <origin rpy="-1.570796 0 0" xyz="0 -0.075 -0.3115"/>
  </joint>
  <link name="at_br_wheel">
    <visual>
      <origin rpy="0 0 0" xyz="0 0 0"/>
      <geometry>
        <cylinder length="0.3" radius="0.523"/>
      </geometry>
      <material name="grey">
        <color rgba="0.1 0.1 0.1 1"/>
      </material>
    </visual>
    <collision>
      <origin rpy="0 0 0" xyz="0 0 0"/>
      <geometry>
        <cylinder length="0.05" radius="0.523"/>
      </geometry>
    </collision>
    <inertial>
      <mass value="100.0"/>
      <origin rpy="0 0 0" xyz="0 0 0"/>
      <inertia ixx="6.8316221" ixy="0.0" ixz="0.0" iyy="6.8316221" iyz="0.0" izz="13.67645"/>
    </inertial>
  </link>
  <!-- ~~~~~~~~~~~~~~~~~~~~~~~~~~~~~~ SENSORS ~~~~~~~~~~~~~~~~~~~~~~~~~~~~~~~~~~~~~~~~~~~ -->
  <!--  front lidar -->
  <joint name="at_platform_2_lidar0" type="fixed">
    <parent link="at_platform"/>
    <child link="at_lidar0"/>
    <origin rpy="0 0 0" xyz="2.845 0 0.1046"/>
  </joint>
  <link name="at_lidar0">
    <visual>
      <origin rpy="0 0 0" xyz="0 0 0"/>
      <geometry>
        <box size="0.15 0.15 0.15"/>
      </geometry>
      <material name="blue">
        <color rgba="0.0 0.0 1. 0.8"/>
      </material>
    </visual>
    <inertial>
      <mass value="1.0"/>
      <origin rpy="0 0 0" xyz="0 0 0"/>
      <inertia ixx="0.003735" ixy="0.0" ixz="0.0" iyy="0.003735" iyz="0.0" izz="0.003735"/>
    </inertial>
  </link>
  <!--  side left lidar -->
  <joint name="at_platform_2_lidar2" type="fixed">
    <parent link="at_platform"/>
    <child link="at_lidar2"/>
    <origin rpy="0 0 1.570796" xyz="1.138 1.4475 0.1046"/>
  </joint>
  <link name="at_lidar2">
    <visual>
      <origin rpy="0 0 0" xyz="0 0 0"/>
      <geometry>
        <box size="0.15 0.15 0.15"/>
      </geometry>
      <material name="blue">
        <color rgba="0.0 0.0 1. 0.8"/>
      </material>
    </visual>
    <inertial>
      <mass value="1.0"/>
      <origin rpy="0 0 0" xyz="0 0 0"/>
      <inertia ixx="0.003735" ixy="0.0" ixz="0.0" iyy="0.003735" iyz="0.0" izz="0.003735"/>
    </inertial>
  </link>
  <!--  side right lidar -->
  <joint name="at_platform_2_lidar3" type="fixed">
    <parent link="at_platform"/>
    <child link="at_lidar3"/>
    <origin rpy="0 0 -1.570796" xyz="1.138 -1.4475 0.1046"/>
  </joint>
  <link name="at_lidar3">
    <visual>
      <origin rpy="0 0 0" xyz="0 0 0"/>
      <geometry>
        <box size="0.15 0.15 0.15"/>
      </geometry>
      <material name="blue">
        <color rgba="0.0 0.0 1. 0.8"/>
      </material>
    </visual>
    <inertial>
      <mass value="1.0"/>
      <origin rpy="0 0 0" xyz="0 0 0"/>
      <inertia ixx="0.003735" ixy="0.0" ixz="0.0" iyy="0.003735" iyz="0.0" izz="0.003735"/>
    </inertial>
  </link>
  <!-- Camera -->
  <joint name="at_platform_2_cam" type="fixed">
    <axis xyz="0 1 0"/>
    <origin rpy="0 0 0" xyz="2.845 0 2.092"/>
    <parent link="at_platform"/>
    <child link="at_cam"/>
  </joint>
  <link name="at_cam">
    <collision>
      <origin rpy="0 0 0" xyz="0 0 0"/>
      <geometry>
        <box size="0.05 0.05 0.05"/>
      </geometry>
    </collision>
    <visual>
      <origin rpy="0 0 0" xyz="0 0 0"/>
      <geometry>
        <box size="0.05 0.05 0.05"/>
      </geometry>
      <material name="red"/>
    </visual>
    <inertial>
      <mass value="1e-5"/>
      <origin rpy="0 0 0" xyz="0 0 0"/>
      <inertia ixx="1e-6" ixy="0" ixz="0" iyy="1e-6" iyz="0" izz="1e-6"/>
    </inertial>
  </link>
  <!-- ~~~~~~~~~~~~~~~~~~~~~~~~~~~~~~ TRANSMISSIONS ~~~~~~~~~~~~~~~~~~~~~~~~~~~~~~~~~~~~~~~~~~~ -->
  <!-- front left steering -->
  <transmission name="at_fl_steer">
    <type>transmission_interface/SimpleTransmission</type>
    <joint name="at_platform_2_fl_hinge">
      <hardwareInterface>EffortJointInterface</hardwareInterface>
    </joint>
    <actuator name="at_fl_steer_motor">
      <hardwareInterface>EffortJointInterface</hardwareInterface>
      <mechanicalReduction>1</mechanicalReduction>
    </actuator>
  </transmission>
  <!-- front right steering -->
  <transmission name="at_fr_steer">
    <type>transmission_interface/SimpleTransmission</type>
    <joint name="at_platform_2_fr_hinge">
      <hardwareInterface>EffortJointInterface</hardwareInterface>
    </joint>
    <actuator name="at_fr_steer_motor">
      <hardwareInterface>EffortJointInterface</hardwareInterface>
      <mechanicalReduction>1</mechanicalReduction>
    </actuator>
  </transmission>
  <!-- front left driving -->
  <transmission name="at_fl_drive">
    <type>transmission_interface/SimpleTransmission</type>
    <joint name="at_fl_hinge_2_wheel">
      <hardwareInterface>EffortJointInterface</hardwareInterface>
    </joint>
    <actuator name="at_fl_drive_motor">
      <hardwareInterface>EffortJointInterface</hardwareInterface>
      <mechanicalReduction>1</mechanicalReduction>
    </actuator>
  </transmission>
  <!-- front right driving -->
  <transmission name="at_fr_drive">
    <type>transmission_interface/SimpleTransmission</type>
    <joint name="at_fr_hinge_2_wheel">
      <hardwareInterface>EffortJointInterface</hardwareInterface>
    </joint>
    <actuator name="at_fr_drive_motor">
      <hardwareInterface>EffortJointInterface</hardwareInterface>
      <mechanicalReduction>1</mechanicalReduction>
    </actuator>
  </transmission>
  <!-- back left driving -->
  <transmission name="at_bl_drive">
    <type>transmission_interface/SimpleTransmission</type>
    <joint name="at_bl_hinge_2_wheel">
      <hardwareInterface>EffortJointInterface</hardwareInterface>
    </joint>
    <actuator name="at_bl_drive_motor">
      <hardwareInterface>EffortJointInterface</hardwareInterface>
      <mechanicalReduction>1</mechanicalReduction>
    </actuator>
  </transmission>
  <!-- back right driving -->
  <transmission name="at_br_drive">
    <type>transmission_interface/SimpleTransmission</type>
    <joint name="at_br_hinge_2_wheel">
      <hardwareInterface>EffortJointInterface</hardwareInterface>
    </joint>
    <actuator name="at_br_drive_motor">
      <hardwareInterface>EffortJointInterface</hardwareInterface>
      <mechanicalReduction>1</mechanicalReduction>
    </actuator>
  </transmission>
</robot>
